Workbook

Sheet Quantity sold by product 
A3: Product Category | B3: Sum of Quantity
A4: Beauty | B4: 771
A5: Clothing | B5: 894
A6: Electronics | B6: 849
A7: Grand Total | B7: 2514

Sheet Dataset Understanding

Sheet Total Sales by Gender
A3: Gender | B3: Sum of Total Amount
A4: Female | B4: 232840
A5: Male | B5: 223160
A6: Grand Total | B6: 456000

Sheet retail_sales_dataset 
A1: Transaction ID | B1: Date | C1: Customer ID | D1: Gender | E1: Age | F1: Product Category | G1: Quantity | H1: Price per Unit | I1: Total Amount
A2: 1 | B2: 45254 | C2: CUST001 | D2: Male | E2: 34 | F2: Beauty | G2: 3 | H2: 50 | I2: 150
A3: 2 | B3: 44984 | C3: CUST002 | D3: Female | E3: 26 | F3: Clothing | G3: 2 | H3: 500 | I3: 1000
A4: 3 | B4: 44939 | C4: CUST003 | D4: Male | E4: 50 | F4: Electronics | G4: 1 | H4: 30 | I4: 30
A5: 4 | B5: 45067 | C5: CUST004 | D5: Male | E5: 37 | F5: Clothing | G5: 1 | H5: 500 | I5: 500
A6: 5 | B6: 45052 | C6: CUST005 | D6: Male | E6: 30 | F6: Beauty | G6: 2 | H6: 50 | I6: 100
A7: 6 | B7: 45041 | C7: CUST006 | D7: Female | E7: 45 | F7: Beauty | G7: 1 | H7: 30 | I7: 30
A8: 7 | B8: 44998 | C8: CUST007 | D8: Male | E8: 46 | F8: Clothing | G8: 2 | H8: 25 | I8: 50
A9: 8 | B9: 44979 | C9: CUST008 | D9: Male | E9: 30 | F9: Electronics | G9: 4 | H9: 25 | I9: 100
A10: 9 | B10: 45273 | C10: CUST009 | D10: Male | E10: 63 | F10: Electronics | G10: 2 | H10: 300 | I10: 600
A11: 10 | B11: 45206 | C11: CUST010 | D11: Female | E11: 52 | F11: Clothing | G11: 4 | H11: 50 | I11: 200
A12: 11 | B12: 44971 | C12: CUST011 | D12: Male | E12: 23 | F12: Clothing | G12: 2 | H12: 50 | I12: 100
A13: 12 | B13: 45229 | C13: CUST012 | D13: Male | E13: 35 | F13: Beauty | G13: 3 | H13: 25 | I13: 75
... A1001: 1000 | B1001: 45028 | C1001: CUST1000 | D1001: Male | E1001: 47 | F1001: Electronics | G1001: 4 | H1001: 30 | I1001: 120

Sheet Total Sales By product Category
A3: Row Labels | B3: Sum of Total Amount
A4: Beauty | B4: 143515
A5: Clothing | B5: 155580
A6: Electronics | B6: 156905
A7: Grand Total | B7: 456000

Sheet Data Quality Check
A1: Transaction ID | B1: Date | C1: Customer ID | D1: Gender | E1: Age | F1: Product Category | G1: Quantity | H1: Price per Unit | I1: Total Amount
A2: 1 | B2: 45254 | C2: CUST001 | D2: Male | E2: 34 | F2: Beauty | G2: 3 | H2: 50 | I2: 150
A3: 2 | B3: 44984 | C3: CUST002 | D3: Female | E3: 26 | F3: Clothing | G3: 2 | H3: 500 | I3: 1000
A4: 3 | B4: 44939 | C4: CUST003 | D4: Male | E4: 50 | F4: Electronics | G4: 1 | H4: 30 | I4: 30
A5: 4 | B5: 45067 | C5: CUST004 | D5: Male | E5: 37 | F5: Clothing | G5: 1 | H5: 500 | I5: 500
A6: 5 | B6: 45052 | C6: CUST005 | D6: Male | E6: 30 | F6: Beauty | G6: 2 | H6: 50 | I6: 100
A7: 6 | B7: 45041 | C7: CUST006 | D7: Female | E7: 45 | F7: Beauty | G7: 1 | H7: 30 | I7: 30
A8: 7 | B8: 44998 | C8: CUST007 | D8: Male | E8: 46 | F8: Clothing | G8: 2 | H8: 25 | I8: 50
A9: 8 | B9: 44979 | C9: CUST008 | D9: Male | E9: 30 | F9: Electronics | G9: 4 | H9: 25 | I9: 100
A10: 9 | B10: 45273 | C10: CUST009 | D10: Male | E10: 63 | F10: Electronics | G10: 2 | H10: 300 | I10: 600
A11: 10 | B11: 45206 | C11: CUST010 | D11: Female | E11: 52 | F11: Clothing | G11: 4 | H11: 50 | I11: 200
A12: 11 | B12: 44971 | C12: CUST011 | D12: Male | E12: 23 | F12: Clothing | G12: 2 | H12: 50 | I12: 100
A13: 12 | B13: 45229 | C13: CUST012 | D13: Male | E13: 35 | F13: Beauty | G13: 3 | H13: 25 | I13: 75
... A1001: 1000 | B1001: 45028 | C1001: CUST1000 | D1001: Male | E1001: 47 | F1001: Electronics | G1001: 4 | H1001: 30 | I1001: 120

Sheet Cleaned Data
A1: Transaction ID | B1: Date | C1: Customer ID | D1: Gender | E1: Age | F1: Product Category | G1: Quantity | H1: Price per Unit | I1: Total Amount | J1: Calclated Toal | K1: Amount check
A2: 44 | B2: 44976 | C2: CUST044 | D2: Female | E2: 22 | F2: Clothing | G2: 1 | H2: 25 | I2: 25 | J2: =Table1[[#This Row],[Quantity]]*Table1[[#This Row],[Price per Unit]] -> 25 | K2: =IF(Table1[[#This Row],[Calclated Toal]]=Table1[[#This Row],[Total Amount]],"Correct","check") -> Correct
A3: 103 | B3: 44943 | C3: CUST103 | D3: Female | E3: 59 | F3: Clothing | G3: 1 | H3: 25 | I3: 25 | J3: =Table1[[#This Row],[Quantity]]*Table1[[#This Row],[Price per Unit]] -> 25 | K3: =IF(Table1[[#This Row],[Calclated Toal]]=Table1[[#This Row],[Total Amount]],"Correct","check") -> Correct
A4: 185 | B4: 44984 | C4: CUST185 | D4: Male | E4: 24 | F4: Clothing | G4: 1 | H4: 25 | I4: 25 | J4: =Table1[[#This Row],[Quantity]]*Table1[[#This Row],[Price per Unit]] -> 25 | K4: =IF(Table1[[#This Row],[Calclated Toal]]=Table1[[#This Row],[Total Amount]],"Correct","check") -> Correct
A5: 191 | B5: 45217 | C5: CUST191 | D5: Male | E5: 64 | F5: Beauty | G5: 1 | H5: 25 | I5: 25 | J5: =Table1[[#This Row],[Quantity]]*Table1[[#This Row],[Price per Unit]] -> 25 | K5: =IF(Table1[[#This Row],[Calclated Toal]]=Table1[[#This Row],[Total Amount]],"Correct","check") -> Correct
A6: 201 | B6: 45208 | C6: CUST201 | D6: Male | E6: 56 | F6: Electronics | G6: 1 | H6: 25 | I6: 25 | J6: =Table1[[#This Row],[Quantity]]*Table1[[#This Row],[Price per Unit]] -> 25 | K6: =IF(Table1[[#This Row],[Calclated Toal]]=Table1[[#This Row],[Total Amount]],"Correct","check") -> Correct
A7: 204 | B7: 45197 | C7: CUST204 | D7: Male | E7: 39 | F7: Beauty | G7: 1 | H7: 25 | I7: 25 | J7: =Table1[[#This Row],[Quantity]]*Table1[[#This Row],[Price per Unit]] -> 25 | K7: =IF(Table1[[#This Row],[Calclated Toal]]=Table1[[#This Row],[Total Amount]],"Correct","check") -> Correct
A8: 205 | B8: 45237 | C8: CUST205 | D8: Female | E8: 43 | F8: Clothing | G8: 1 | H8: 25 | I8: 25 | J8: =Table1[[#This Row],[Quantity]]*Table1[[#This Row],[Price per Unit]] -> 25 | K8: =IF(Table1[[#This Row],[Calclated Toal]]=Table1[[#This Row],[Total Amount]],"Correct","check") -> Correct
A9: 206 | B9: 45143 | C9: CUST206 | D9: Male | E9: 61 | F9: Clothing | G9: 1 | H9: 25 | I9: 25 | J9: =Table1[[#This Row],[Quantity]]*Table1[[#This Row],[Price per Unit]] -> 25 | K9: =IF(Table1[[#This Row],[Calclated Toal]]=Table1[[#This Row],[Total Amount]],"Correct","check") -> Correct
A10: 223 | B10: 44959 | C10: CUST223 | D10: Female | E10: 64 | F10: Clothing | G10: 1 | H10: 25 | I10: 25 | J10: =Table1[[#This Row],[Quantity]]*Table1[[#This Row],[Price per Unit]] -> 25 | K10: =IF(Table1[[#This Row],[Calclated Toal]]=Table1[[#This Row],[Total Amount]],"Correct","check") -> Correct
A11: 230 | B11: 45039 | C11: CUST230 | D11: Male | E11: 54 | F11: Beauty | G11: 1 | H11: 25 | I11: 25 | J11: =Table1[[#This Row],[Quantity]]*Table1[[#This Row],[Price per Unit]] -> 25 | K11: =IF(Table1[[#This Row],[Calclated Toal]]=Table1[[#This Row],[Total Amount]],"Correct","check") -> Correct
A12: 232 | B12: 44963 | C12: CUST232 | D12: Female | E12: 43 | F12: Beauty | G12: 1 | H12: 25 | I12: 25 | J12: =Table1[[#This Row],[Quantity]]*Table1[[#This Row],[Price per Unit]] -> 25 | K12: =IF(Table1[[#This Row],[Calclated Toal]]=Table1[[#This Row],[Total Amount]],"Correct","check") -> Correct
A13: 236 | B13: 45044 | C13: CUST236 | D13: Female | E13: 54 | F13: Clothing | G13: 1 | H13: 25 | I13: 25 | J13: =Table1[[#This Row],[Quantity]]*Table1[[#This Row],[Price per Unit]] -> 25 | K13: =IF(Table1[[#This Row],[Calclated Toal]]=Table1[[#This Row],[Total Amount]],"Correct","check") -> Correct
... A297: 56 | B297: 45077 | C297: CUST056 | D297: Female | E297: 26 | F297: Clothing | G297: 3 | H297: 300 | I297: 900 | J297: =Table1[[#This Row],[Quantity]]*Table1[[#This Row],[Price per Unit]] -> 900 | K297: =IF(Table1[[#This Row],[Calclated Toal]]=Table1[[#This Row],[Total Amount]],"Correct","check") -> Correct
A298: 78 | B298: 45108 | C298: CUST078 | D298: Female | E298: 47 | F298: Clothing | G298: 3 | H298: 500 | I298: 1500 | J298: =Table1[[#This Row],[Quantity]]*Table1[[#This Row],[Price per Unit]] -> 1500 | K298: =IF(Table1[[#This Row],[Calclated Toal]]=Table1[[#This Row],[Total Amount]],"Correct","check") -> Correct | M298: =MIN(E:E) -> 18
A299: 872 | B299: 45210 | C299: CUST872 | D299: Female | E299: 63 | F299: Beauty | G299: 3 | H299: 25 | I299: 75 | J299: =Table1[[#This Row],[Quantity]]*Table1[[#This Row],[Price per Unit]] -> 75 | K299: =IF(Table1[[#This Row],[Calclated Toal]]=Table1[[#This Row],[Total Amount]],"Correct","check") -> Correct
A300: 920 | B300: 44979 | C300: CUST920 | D300: Female | E300: 28 | F300: Beauty | G300: 3 | H300: 25 | I300: 75 | J300: =Table1[[#This Row],[Quantity]]*Table1[[#This Row],[Price per Unit]] -> 75 | K300: =IF(Table1[[#This Row],[Calclated Toal]]=Table1[[#This Row],[Total Amount]],"Correct","check") -> Correct
A301: 921 | B301: 44933 | C301: CUST921 | D301: Male | E301: 51 | F301: Electronics | G301: 3 | H301: 25 | I301: 75 | J301: =Table1[[#This Row],[Quantity]]*Table1[[#This Row],[Price per Unit]] -> 75 | K301: =IF(Table1[[#This Row],[Calclated Toal]]=Table1[[#This Row],[Total Amount]],"Correct","check") -> Correct
A302: 929 | B302: 44953 | C302: CUST929 | D302: Female | E302: 23 | F302: Beauty | G302: 3 | H302: 25 | I302: 75 | J302: =Table1[[#This Row],[Quantity]]*Table1[[#This Row],[Price per Unit]] -> 75 | K302: =IF(Table1[[#This Row],[Calclated Toal]]=Table1[[#This Row],[Total Amount]],"Correct","check") -> Correct
A303: 948 | B303: 45212 | C303: CUST948 | D303: Female | E303: 23 | F303: Electronics | G303: 3 | H303: 25 | I303: 75 | J303: =Table1[[#This Row],[Quantity]]*Table1[[#This Row],[Price per Unit]] -> 75 | K303: =IF(Table1[[#This Row],[Calclated Toal]]=Table1[[#This Row],[Total Amount]],"Correct","check") -> Correct
A304: 977 | B304: 44965 | C304: CUST977 | D304: Female | E304: 35 | F304: Electronics | G304: 3 | H304: 25 | I304: 75 | J304: =Table1[[#This Row],[Quantity]]*Table1[[#This Row],[Price per Unit]] -> 75 | K304: =IF(Table1[[#This Row],[Calclated Toal]]=Table1[[#This Row],[Total Amount]],"Correct","check") -> Correct
A305: 980 | B305: 45136 | C305: CUST980 | D305: Female | E305: 31 | F305: Electronics | G305: 3 | H305: 25 | I305: 75 | J305: =Table1[[#This Row],[Quantity]]*Table1[[#This Row],[Price per Unit]] -> 75 | K305: =IF(Table1[[#This Row],[Calclated Toal]]=Table1[[#This Row],[Total Amount]],"Correct","check") -> Correct
A306: 107 | B306: 44960 | C306: CUST107 | D306: Female | E306: 21 | F306: Clothing | G306: 4 | H306: 300 | I306: 1200 | J306: =Table1[[#This Row],[Quantity]]*Table1[[#This Row],[Price per Unit]] -> 1200 | K306: =IF(Table1[[#This Row],[Calclated Toal]]=Table1[[#This Row],[Total Amount]],"Correct","check") -> Correct | M306: =MAX(E:E) -> 64
A307: 32 | B307: 44930 | C307: CUST032 | D307: Male | E307: 30 | F307: Beauty | G307: 3 | H307: 30 | I307: 90 | J307: =Table1[[#This Row],[Quantity]]*Table1[[#This Row],[Price per Unit]] -> 90 | K307: =IF(Table1[[#This Row],[Calclated Toal]]=Table1[[#This Row],[Total Amount]],"Correct","check") -> Correct
A308: 73 | B308: 45159 | C308: CUST073 | D308: Male | E308: 29 | F308: Electronics | G308: 3 | H308: 30 | I308: 90 | J308: =Table1[[#This Row],[Quantity]]*Table1[[#This Row],[Price per Unit]] -> 90 | K308: =IF(Table1[[#This Row],[Calclated Toal]]=Table1[[#This Row],[Total Amount]],"Correct","check") -> Correct
A309: 84 | B309: 45258 | C309: CUST084 | D309: Female | E309: 38 | F309: Electronics | G309: 3 | H309: 30 | I309: 90 | J309: =Table1[[#This Row],[Quantity]]*Table1[[#This Row],[Price per Unit]] -> 90 | K309: =IF(Table1[[#This Row],[Calclated Toal]]=Table1[[#This Row],[Total Amount]],"Correct","check") -> Correct
A310: 86 | B310: 45238 | C310: CUST086 | D310: Male | E310: 19 | F310: Beauty | G310: 3 | H310: 30 | I310: 90 | J310: =Table1[[#This Row],[Quantity]]*Table1[[#This Row],[Price per Unit]] -> 90 | K310: =IF(Table1[[#This Row],[Calclated Toal]]=Table1[[#This Row],[Total Amount]],"Correct","check") -> Correct
A311: 119 | B311: 44998 | C311: CUST119 | D311: Female | E311: 60 | F311: Clothing | G311: 3 | H311: 50 | I311: 150 | J311: =Table1[[#This Row],[Quantity]]*Table1[[#This Row],[Price per Unit]] -> 150 | K311: =IF(Table1[[#This Row],[Calclated Toal]]=Table1[[#This Row],[Total Amount]],"Correct","check") -> Correct
A312: 190 | B312: 45050 | C312: CUST190 | D312: Female | E312: 60 | F312: Beauty | G312: 3 | H312: 30 | I312: 90 | J312: =Table1[[#This Row],[Quantity]]*Table1[[#This Row],[Price per Unit]] -> 90 | K312: =IF(Table1[[#This Row],[Calclated Toal]]=Table1[[#This Row],[Total Amount]],"Correct","check") -> Correct
A313: 218 | B313: 45191 | C313: CUST218 | D313: Male | E313: 64 | F313: Beauty | G313: 3 | H313: 30 | I313: 90 | J313: =Table1[[#This Row],[Quantity]]*Table1[[#This Row],[Price per Unit]] -> 90 | K313: =IF(Table1[[#This Row],[Calclated Toal]]=Table1[[#This Row],[Total Amount]],"Correct","check") -> Correct
A314: 219 | B314: 45158 | C314: CUST219 | D314: Female | E314: 53 | F314: Electronics | G314: 3 | H314: 30 | I314: 90 | J314: =Table1[[#This Row],[Quantity]]*Table1[[#This Row],[Price per Unit]] -> 90 | K314: =IF(Table1[[#This Row],[Calclated Toal]]=Table1[[#This Row],[Total Amount]],"Correct","check") -> Correct
A315: 229 | B315: 45228 | C315: CUST229 | D315: Male | E315: 58 | F315: Beauty | G315: 3 | H315: 30 | I315: 90 | J315: =Table1[[#This Row],[Quantity]]*Table1[[#This Row],[Price per Unit]] -> 90 | K315: =IF(Table1[[#This Row],[Calclated Toal]]=Table1[[#This Row],[Total Amount]],"Correct","check") -> Correct
A316: 245 | B316: 45175 | C316: CUST245 | D316: Male | E316: 47 | F316: Clothing | G316: 3 | H316: 30 | I316: 90 | J316: =Table1[[#This Row],[Quantity]]*Table1[[#This Row],[Price per Unit]] -> 90 | K316: =IF(Table1[[#This Row],[Calclated Toal]]=Table1[[#This Row],[Total Amount]],"Correct","check") -> Correct
A317: 267 | B317: 45257 | C317: CUST267 | D317: Female | E317: 32 | F317: Beauty | G317: 3 | H317: 30 | I317: 90 | J317: =Table1[[#This Row],[Quantity]]*Table1[[#This Row],[Price per Unit]] -> 90 | K317: =IF(Table1[[#This Row],[Calclated Toal]]=Table1[[#This Row],[Total Amount]],"Correct","check") -> Correct
A318: 293 | B318: 45048 | C318: CUST293 | D318: Male | E318: 50 | F318: Electronics | G318: 3 | H318: 30 | I318: 90 | J318: =Table1[[#This Row],[Quantity]]*Table1[[#This Row],[Price per Unit]] -> 90 | K318: =IF(Table1[[#This Row],[Calclated Toal]]=Table1[[#This Row],[Total Amount]],"Correct","check") -> Correct
... A322: 331 | B322: 44968 | C322: CUST331 | D322: Male | E322: 28 | F322: Electronics | G322: 3 | H322: 30 | I322: 90 | J322: =Table1[[#This Row],[Quantity]]*Table1[[#This Row],[Price per Unit]] -> 90 | K322: =IF(Table1[[#This Row],[Calclated Toal]]=Table1[[#This Row],[Total Amount]],"Correct","check") -> Correct
A323: 145 | B323: 45232 | C323: CUST145 | D323: Female | E323: 39 | F323: Clothing | G323: 3 | H323: 25 | I323: 75 | J323: =Table1[[#This Row],[Quantity]]*Table1[[#This Row],[Price per Unit]] -> 75 | K323: =IF(Table1[[#This Row],[Calclated Toal]]=Table1[[#This Row],[Total Amount]],"Correct","check") -> Correct | M323: =MIN(G:G) -> 1
A324: 383 | B324: 45007 | C324: CUST383 | D324: Female | E324: 46 | F324: Beauty | G324: 3 | H324: 30 | I324: 90 | J324: =Table1[[#This Row],[Quantity]]*Table1[[#This Row],[Price per Unit]] -> 90 | K324: =IF(Table1[[#This Row],[Calclated Toal]]=Table1[[#This Row],[Total Amount]],"Correct","check") -> Correct
A325: 156 | B325: 45255 | C325: CUST156 | D325: Female | E325: 43 | F325: Clothing | G325: 4 | H325: 25 | I325: 100 | J325: =Table1[[#This Row],[Quantity]]*Table1[[#This Row],[Price per Unit]] -> 100 | K325: =IF(Table1[[#This Row],[Calclated Toal]]=Table1[[#This Row],[Total Amount]],"Correct","check") -> Correct | M325: =MIN(H:H) -> 25
A326: 163 | B326: 44928 | C326: CUST163 | D326: Female | E326: 64 | F326: Clothing | G326: 3 | H326: 50 | I326: 150 | J326: =Table1[[#This Row],[Quantity]]*Table1[[#This Row],[Price per Unit]] -> 150 | K326: =IF(Table1[[#This Row],[Calclated Toal]]=Table1[[#This Row],[Total Amount]],"Correct","check") -> Correct
...

Sheet Sorting and filtering ss 

Sheet Basic Analysis
A1: Total Sales Amount | B1: =SUM('Cleaned Data'!I:I) -> 456000 | F1: Product Category | G1: Total Sales | I1: Product Category | J1: Quantity Sold
A2: Average Sales Amount | B2: =AVERAGE('Cleaned Data'!I:I) -> 456 | F2: Beauty | G2: =SUMIF('Cleaned Data'!F:F,"Beauty",'Cleaned Data'!I:I) -> 143515 | I2: Beauty | J2: =SUMIF('Cleaned Data'!F:F,"Beauty",'Cleaned Data'!G:G) -> 771
A3: Min Sales Amount | B3: =MIN('Cleaned Data'!I:I) -> 25 | F3: Clothing | G3: =SUMIF('Cleaned Data'!F:F,"Clothing",'Cleaned Data'!I:I) -> 155580 | I3: Clothing | J3: =SUMIF('Cleaned Data'!F:F,"Clothing",'Cleaned Data'!G:G) -> 894
A4: Max Sales Amount | B4: =MAX('Cleaned Data'!I:I) -> 2000 | F4: Electronics | G4: =SUMIF('Cleaned Data'!F:F,"Electronics",'Cleaned Data'!I:I) -> 156905 | I4: Electronics | J4: =SUMIF('Cleaned Data'!F:F,"Electronics",'Cleaned Data'!G:G) -> 849
A5: Total Quantity Sold | B5: =SUM('Cleaned Data'!G:G) -> 2514
A6: Average Customer age | B6: =AVERAGE('Cleaned Data'!E:E) -> 41.392
A7: Total Transactions | B7: =COUNT('Cleaned Data'!A:A) -> 1000 | F7: Gender | G7: Total Sales
A8: Total Number of Uniqu Categories | B8: 3 | F8: Male | G8: =SUMIF('Cleaned Data'!D:D,"Male",'Cleaned Data'!I:I) -> 223160
A9: Youngest Customer Age | B9: 18 | F9: Female | G9: =SUMIF('Cleaned Data'!D:D,"Male",'Cleaned Data'!I:I) -> 223160
A10: Oldest Customer age | B10: 64

Sheet Basic Charts

Sheet Observations
